<sdf version='1.7'>
  <world name='default' xmlns:xacro='http://www.ros.org/wiki/xacro'>
    <physics type='ode'>
      <max_step_size>0.001</max_step_size>
      <real_time_factor>1</real_time_factor>
      <real_time_update_rate>1000</real_time_update_rate>
    </physics>
    <light name='sun' type='directional'>
      <cast_shadows>1</cast_shadows>
      <pose>0 0 10 0 -0 0</pose>
      <diffuse>0.8 0.8 0.8 1</diffuse>
      <specular>0.2 0.2 0.2 1</specular>
      <attenuation>
        <range>1000</range>
        <constant>0.9</constant>
        <linear>0.01</linear>
        <quadratic>0.001</quadratic>
      </attenuation>
      <direction>-0.5 0.1 -0.9</direction>
      <spot>
        <inner_angle>0</inner_angle>
        <outer_angle>0</outer_angle>
        <falloff>0</falloff>
      </spot>
    </light>
    <model name='ground_plane'>
      <static>1</static>
      <link name='link'>
        <collision name='collision'>
          <geometry>
            <plane>
              <normal>0 0 1</normal>
              <size>100 100</size>
            </plane>
          </geometry>
          <surface>
            <contact>
              <collide_bitmask>65535</collide_bitmask>
              <ode/>
            </contact>
            <friction>
              <ode>
                <mu>100</mu>
                <mu2>50</mu2>
              </ode>
              <torsional>
                <ode/>
              </torsional>
            </friction>
            <bounce/>
          </surface>
          <max_contacts>10</max_contacts>
        </collision>
        <visual name='visual'>
          <cast_shadows>0</cast_shadows>
          <geometry>
            <plane>
              <normal>0 0 1</normal>
              <size>100 100</size>
            </plane>
          </geometry>
          <material>
            <script>
              <uri>file://media/materials/scripts/gazebo.material</uri>
              <name>Gazebo/Grey</name>
            </script>
          </material>
        </visual>
        <self_collide>0</self_collide>
        <enable_wind>0</enable_wind>
        <kinematic>0</kinematic>
      </link>
    </model>
    <gravity>0 0 -9.8</gravity>
    <magnetic_field>6e-06 2.3e-05 -4.2e-05</magnetic_field>
    <atmosphere type='adiabatic'/>
    <scene>
      <ambient>0.4 0.4 0.4 1</ambient>
      <background>0.7 0.7 0.7 1</background>
      <shadows>1</shadows>
    </scene>
    <wind/>
    <spherical_coordinates>
      <surface_model>EARTH_WGS84</surface_model>
      <latitude_deg>0</latitude_deg>
      <longitude_deg>0</longitude_deg>
      <elevation>0</elevation>
      <heading_deg>0</heading_deg>
    </spherical_coordinates>
    <model name='door'>
      <pose>-1.64577 1.97943 0 1.5708 -0 0</pose>
      <link name='door_frame'>
        <inertial>
          <pose>0.105 0.2 0.01 0 -0 0</pose>
          <mass>30</mass>
          <inertia>
            <ixx>1</ixx>
            <ixy>0</ixy>
            <ixz>0</ixz>
            <iyy>1</iyy>
            <iyz>0</iyz>
            <izz>1</izz>
          </inertia>
        </inertial>
        <visual name='visual_frame'>
          <pose>0 0 0 0 -0 0</pose>
          <geometry>
            <mesh>
              <uri>model://door/meshes/frame.stl</uri>
              <scale>0.1 0.1 0.1</scale>
            </mesh>
          </geometry>
        </visual>
        <collision name='collision_frame'>
          <pose>0 0 0 0 -0 0</pose>
          <geometry>
            <mesh>
              <uri>model://door/meshes/frame.stl</uri>
              <scale>0.1 0.1 0.1</scale>
            </mesh>
          </geometry>
          <max_contacts>10</max_contacts>
          <surface>
            <contact>
              <ode/>
            </contact>
            <bounce/>
            <friction>
              <torsional>
                <ode/>
              </torsional>
              <ode/>
            </friction>
          </surface>
        </collision>
        <self_collide>0</self_collide>
        <enable_wind>0</enable_wind>
        <kinematic>0</kinematic>
      </link>
      <link name='door_body'>
        <inertial>
          <pose>0.505 1.005 0.01 0 -0 0</pose>
          <mass>1</mass>
          <inertia>
            <ixx>0.083</ixx>
            <ixy>0</ixy>
            <ixz>0</ixz>
            <iyy>0.083</iyy>
            <iyz>0</iyz>
            <izz>0.083</izz>
          </inertia>
        </inertial>
        <collision name='collision_door'>
          <pose>0.505 1.005 0.01 0 -0 0</pose>
          <geometry>
            <box>
              <size>1 2 0.006</size>
            </box>
          </geometry>
          <max_contacts>10</max_contacts>
          <surface>
            <contact>
              <ode/>
            </contact>
            <bounce/>
            <friction>
              <torsional>
                <ode/>
              </torsional>
              <ode/>
            </friction>
          </surface>
        </collision>
        <visual name='visual_door'>
          <pose>0.505 1.005 0.01 0 -0 0</pose>
          <geometry>
            <box>
              <size>1 2 0.006</size>
            </box>
          </geometry>
        </visual>
        <self_collide>0</self_collide>
        <enable_wind>0</enable_wind>
        <kinematic>0</kinematic>
      </link>
      <link name='door_handle'>
        <inertial>
          <pose>0.2 0.9 0.01 0 -0 0</pose>
          <mass>1</mass>
          <inertia>
            <ixx>1</ixx>
            <ixy>0</ixy>
            <ixz>0</ixz>
            <iyy>1</iyy>
            <iyz>0</iyz>
            <izz>1</izz>
          </inertia>
        </inertial>
        <visual name='visual_handle'>
          <pose>0.2 0.9 0.01 0 -0 0</pose>
          <geometry>
            <mesh>
              <uri>model://door/meshes/handle.stl</uri>
              <scale>0.002 0.002 0.002</scale>
            </mesh>
          </geometry>
        </visual>
        <collision name='collision_handle'>
          <pose>0.2 0.9 0.01 0 -0 0</pose>
          <geometry>
            <mesh>
              <uri>model://door/meshes/handle.stl</uri>
              <scale>0.002 0.002 0.002</scale>
            </mesh>
          </geometry>
          <max_contacts>10</max_contacts>
          <surface>
            <contact>
              <ode/>
            </contact>
            <bounce/>
            <friction>
              <torsional>
                <ode/>
              </torsional>
              <ode/>
            </friction>
          </surface>
        </collision>
        <self_collide>0</self_collide>
        <enable_wind>0</enable_wind>
        <kinematic>0</kinematic>
      </link>
      <joint name='handle_joint' type='fixed'>
        <parent>door_body</parent>
        <child>door_handle</child>
        <pose>0.55 0.9 0.01 0 -0 0</pose>
      </joint>
      <joint name='door_hinge' type='revolute'>
        <parent>door_frame</parent>
        <child>door_body</child>
        <pose>0.95 1.005 0.01 0 -0 0</pose>
        <axis>
          <xyz expressed_in='__model__'>0 0 1</xyz>
          <dynamics>
            <damping>0.1</damping>
            <friction>0.1</friction>
            <spring_reference>0</spring_reference>
            <spring_stiffness>0</spring_stiffness>
          </dynamics>
          <limit>
            <lower>0</lower>
            <upper>1.57</upper>
          </limit>
        </axis>
      </joint>
      <joint name='world_joint' type='revolute'>
        <child>door_frame</child>
        <parent>world</parent>
        <axis>
          <limit>
            <lower>0</lower>
            <upper>0</upper>
          </limit>
          <xyz expressed_in='__model__'>0 1 0</xyz>
          <dynamics>
            <damping>1</damping>
            <spring_reference>0</spring_reference>
            <spring_stiffness>0</spring_stiffness>
          </dynamics>
        </axis>
        <physics>
          <ode>
            <cfm_damping>1</cfm_damping>
            <limit>
              <cfm>0</cfm>
              <erp>0.2</erp>
            </limit>
          </ode>
        </physics>
      </joint>
    </model>
    <state world_name='default'>
      <sim_time>53 564000000</sim_time>
      <real_time>53 737316324</real_time>
      <wall_time>1747234594 897860284</wall_time>
      <iterations>53564</iterations>
      <model name='door'>
        <pose>-1.64577 1.97943 0 1.5708 -0 0</pose>
        <scale>1 1 1</scale>
        <link name='door_body'>
          <pose>-1.64042 1.97943 -0.005027 1.5708 -0.005311 -0</pose>
          <velocity>-2.9e-05 -0 -3.8e-05 0.000159 -9.2e-05 0.000134</velocity>
          <acceleration>-0.268437 -0.192204 0.04733 0.320489 -0.265726 0.261239</acceleration>
          <wrench>-0.268437 -0.192204 0.04733 0 -0 0</wrench>
        </link>
        <link name='door_frame'>
          <pose>-1.64577 1.97943 0 1.5708 -0 0</pose>
          <velocity>-1e-06 -3e-06 -6.5e-05 0.000126 -0.000124 7e-06</velocity>
          <acceleration>-0.065023 -0.052375 -0.101324 0.266456 -0.242513 0.138903</acceleration>
          <wrench>-1.9507 -1.57126 -3.03973 0 -0 0</wrench>
        </link>
        <link name='door_handle'>
          <pose>-1.64043 1.97943 -0.005024 1.5708 -0.005305 0</pose>
          <velocity>-3.3e-05 -4e-06 -3.6e-05 0.000156 -8.9e-05 0.000135</velocity>
          <acceleration>-0.253061 -0.23979 -0.01307 0.316683 -0.198043 0.26414</acceleration>
          <wrench>-0.253061 -0.23979 -0.01307 0 -0 0</wrench>
        </link>
      </model>
      <model name='ground_plane'>
        <pose>0 0 0 0 -0 0</pose>
        <scale>1 1 1</scale>
        <link name='link'>
          <pose>0 0 0 0 -0 0</pose>
          <velocity>0 0 0 0 -0 0</velocity>
          <acceleration>0 0 0 0 -0 0</acceleration>
          <wrench>0 0 0 0 -0 0</wrench>
        </link>
      </model>
      <light name='sun'>
        <pose>0 0 10 0 -0 0</pose>
      </light>
    </state>
    <gui fullscreen='0'>
      <camera name='user_camera'>
        <pose>0.748715 -5.68911 2.93613 0 0.267643 1.9802</pose>
        <view_controller>orbit</view_controller>
        <projection_type>perspective</projection_type>
      </camera>
    </gui>
  </world>
</sdf>
